{
 "cells": [
  {
   "cell_type": "markdown",
   "metadata": {},
   "source": [
    "## 9. Testing and Debugging"
   ]
  },
  {
   "cell_type": "markdown",
   "metadata": {},
   "source": [
    "### 76 Verify Related Behaviors in `TestCase` Subclasses"
   ]
  },
  {
   "cell_type": "markdown",
   "metadata": {},
   "source": [
    "```python\n",
    "# utils.py\n",
    "\n",
    "def to_str(data):\n",
    "    if isinstance(data, str):\n",
    "        return data\n",
    "    elif isinstance(data, bytes):\n",
    "        return data.decode('utf-8')\n",
    "    else:\n",
    "        raise TypeError('Must supply str or bytes, '\n",
    "                        'found: %r' % data)\n",
    "```"
   ]
  },
  {
   "cell_type": "markdown",
   "metadata": {},
   "source": [
    "```python\n",
    "# utils_test.py\n",
    "\n",
    "from unittest import TestCase, main\n",
    "from utils import to_str\n",
    "\n",
    "class UtilsTestCase(TestCase):\n",
    "    def test_to_str_bytes(self):\n",
    "        self.assertEqual('hello', to_str(b'hello'))\n",
    "\n",
    "    def test_to_str_str(self):\n",
    "        self.assertEqual('hello', to_str('hello'))\n",
    "\n",
    "    def test_failing(self):\n",
    "        self.assertEqual('incorrect', to_str('hello'))\n",
    "\n",
    "if __name__ == '__main__':\n",
    "    main()\n",
    "```"
   ]
  },
  {
   "cell_type": "markdown",
   "metadata": {},
   "source": [
    "```shell\n",
    "$ python utils_test.py \n",
    "F..\n",
    "======================================================================\n",
    "FAIL: test_failing (__main__.UtilsTestCase)\n",
    "----------------------------------------------------------------------\n",
    "Traceback (most recent call last):\n",
    "  File \"utils_test.py\", line 28, in test_failing\n",
    "    self.assertEqual('incorrect', to_str('hello'))\n",
    "AssertionError: 'incorrect' != 'hello'\n",
    "- incorrect\n",
    "+ hello\n",
    "\n",
    "\n",
    "----------------------------------------------------------------------\n",
    "Ran 3 tests in 0.001s\n",
    "\n",
    "FAILED (failures=1)\n",
    "```"
   ]
  },
  {
   "cell_type": "markdown",
   "metadata": {},
   "source": [
    "```shell\n",
    "$ python utils_test.py UtilsTestCase.test_to_str_bytes \n",
    ".\n",
    "----------------------------------------------------------------------\n",
    "Ran 1 test in 0.000s\n",
    "\n",
    "OK\n",
    "```"
   ]
  },
  {
   "cell_type": "markdown",
   "metadata": {},
   "source": [
    "```python\n",
    "# assert_test.py\n",
    "\n",
    "from unittest import TestCase, main\n",
    "from utils import to_str\n",
    "\n",
    "class AssertTestCase(TestCase):\n",
    "    def test_assert_helper(self):\n",
    "        expected = 12\n",
    "        found = 2 * 5\n",
    "        self.assertEqual(expected, found)\n",
    "\n",
    "    def test_assert_statement(self):\n",
    "        expected = 12\n",
    "        found = 2 * 5\n",
    "        assert expected == found\n",
    "\n",
    "if __name__ == '__main__':\n",
    "    main()\n",
    "```"
   ]
  },
  {
   "cell_type": "markdown",
   "metadata": {},
   "source": [
    "```shell\n",
    "$ python assert_test.py\n",
    "FF\n",
    "======================================================================\n",
    "FAIL: test_assert_helper (__main__.AssertTestCase)\n",
    "----------------------------------------------------------------------\n",
    "Traceback (most recent call last):\n",
    "  File \"assert_test.py\", line 24, in test_assert_helper\n",
    "    self.assertEqual(expected, found)\n",
    "AssertionError: 12 != 10\n",
    "\n",
    "======================================================================\n",
    "FAIL: test_assert_statement (__main__.AssertTestCase)\n",
    "----------------------------------------------------------------------\n",
    "Traceback (most recent call last):\n",
    "  File \"assert_test.py\", line 29, in test_assert_statement\n",
    "    assert expected == found\n",
    "AssertionError\n",
    "\n",
    "----------------------------------------------------------------------\n",
    "Ran 2 tests in 0.001s\n",
    "\n",
    "FAILED (failures=2)\n",
    "```"
   ]
  },
  {
   "cell_type": "markdown",
   "metadata": {},
   "source": [
    "```python\n",
    "# utils_error_test.py\n",
    "\n",
    "from unittest import TestCase, main\n",
    "from utils import to_str\n",
    "\n",
    "class UtilsErrorTestCase(TestCase):\n",
    "    def test_to_str_bad(self):\n",
    "        with self.assertRaises(TypeError):\n",
    "            to_str(object())\n",
    "\n",
    "    def test_to_str_bad_encoding(self):\n",
    "        with self.assertRaises(UnicodeDecodeError):\n",
    "            to_str(b'\\xfa\\xfa')\n",
    "\n",
    "if __name__ == '__main__':\n",
    "    main()\n",
    "```"
   ]
  },
  {
   "cell_type": "markdown",
   "metadata": {},
   "source": [
    "```shell\n",
    "$ python utils_error_test.py\n",
    "..\n",
    "----------------------------------------------------------------------\n",
    "Ran 2 tests in 0.000s\n",
    "\n",
    "OK\n",
    "```"
   ]
  },
  {
   "cell_type": "markdown",
   "metadata": {},
   "source": [
    "```python\n",
    "# helper_test.py\n",
    "\n",
    "from unittest import TestCase, main\n",
    "\n",
    "def sum_squares(values):\n",
    "    cumulative = 0\n",
    "    for value in values:\n",
    "        cumulative += value ** 2\n",
    "        yield cumulative\n",
    "\n",
    "class HelperTestCase(TestCase):\n",
    "    def verify_complex_case(self, values, expected):\n",
    "        expect_it = iter(expected)\n",
    "        found_it = iter(sum_squares(values))\n",
    "        test_it = zip(expect_it, found_it)\n",
    "\n",
    "        for i, (expect, found) in enumerate(test_it):\n",
    "            self.assertEqual(\n",
    "                expect,\n",
    "                found,\n",
    "                f'Index {i} is wrong')\n",
    "\n",
    "        # Verify both generators are exhausted\n",
    "        try:\n",
    "            next(expect_it)\n",
    "        except StopIteration:\n",
    "            pass\n",
    "        else:\n",
    "            self.fail('Expected longer than found')\n",
    "\n",
    "        try:\n",
    "            next(found_it)\n",
    "        except StopIteration:\n",
    "            pass\n",
    "        else:\n",
    "            self.fail('Found longer than expected')\n",
    "\n",
    "    def test_wrong_lengths(self):\n",
    "        values = [1.1, 2.2, 3.3]\n",
    "        expected = [\n",
    "            1.1**2,\n",
    "        ]\n",
    "        self.verify_complex_case(values, expected)\n",
    "\n",
    "    def test_wrong_results(self):\n",
    "        values = [1.1, 2.2, 3.3]\n",
    "        expected = [\n",
    "            1.1**2,\n",
    "            1.1**2 + 2.2**2,\n",
    "            1.1**2 + 2.2**2 + 3.3**2 + 4.4**2,\n",
    "        ]\n",
    "        self.verify_complex_case(values, expected)\n",
    "\n",
    "if __name__ == '__main__':\n",
    "    main()\n",
    "```"
   ]
  },
  {
   "cell_type": "markdown",
   "metadata": {},
   "source": [
    "```shell\n",
    "$ python helper_test.py \n",
    "FF\n",
    "======================================================================\n",
    "FAIL: test_wrong_lengths (__main__.HelperTestCase)\n",
    "----------------------------------------------------------------------\n",
    "Traceback (most recent call last):\n",
    "  File \"helper_test.py\", line 57, in test_wrong_lengths\n",
    "    self.verify_complex_case(values, expected)\n",
    "  File \"helper_test.py\", line 50, in verify_complex_case\n",
    "    self.fail('Found longer than expected')\n",
    "AssertionError: Found longer than expected\n",
    "\n",
    "======================================================================\n",
    "FAIL: test_wrong_results (__main__.HelperTestCase)\n",
    "----------------------------------------------------------------------\n",
    "Traceback (most recent call last):\n",
    "  File \"helper_test.py\", line 66, in test_wrong_results\n",
    "    self.verify_complex_case(values, expected)\n",
    "  File \"helper_test.py\", line 32, in verify_complex_case\n",
    "    self.assertEqual(\n",
    "AssertionError: 36.3 != 16.939999999999998 : Index 2 is wrong\n",
    "\n",
    "----------------------------------------------------------------------\n",
    "Ran 2 tests in 0.001s\n",
    "\n",
    "FAILED (failures=2)\n",
    "```"
   ]
  },
  {
   "cell_type": "markdown",
   "metadata": {},
   "source": [
    "```python\n",
    "# data_driven_test.py\n",
    "\n",
    "from unittest import TestCase, main\n",
    "from utils import to_str\n",
    "\n",
    "class DataDrivenTestCase(TestCase):\n",
    "    def test_good(self):\n",
    "        good_cases = [\n",
    "            (b'my bytes', 'my bytes'),\n",
    "            ('no error', b'no error'),  # This one will fail\n",
    "            ('other str', 'other str'),\n",
    "        ]\n",
    "        for value, expected in good_cases:\n",
    "            with self.subTest(value):\n",
    "                self.assertEqual(expected, to_str(value))\n",
    "\n",
    "    def test_bad(self):\n",
    "        bad_cases = [\n",
    "            (object(), TypeError),\n",
    "            (b'\\xfa\\xfa', UnicodeDecodeError),\n",
    "        ]\n",
    "        for value, exception in bad_cases:\n",
    "            with self.subTest(value):\n",
    "                with self.assertRaises(exception):\n",
    "                    to_str(value)\n",
    "\n",
    "if __name__ == '__main__':\n",
    "    main()\n",
    "```"
   ]
  },
  {
   "cell_type": "markdown",
   "metadata": {},
   "source": [
    "```shell\n",
    "$ python data_driven_test.py\n",
    ".\n",
    "======================================================================\n",
    "FAIL: test_good (__main__.DataDrivenTestCase) [no error]\n",
    "----------------------------------------------------------------------\n",
    "Traceback (most recent call last):\n",
    "  File \"data_driven_test.py\", line 29, in test_good\n",
    "    self.assertEqual(expected, to_str(value))\n",
    "AssertionError: b'no error' != 'no error'\n",
    "\n",
    "----------------------------------------------------------------------\n",
    "Ran 2 tests in 0.001s\n",
    "\n",
    "FAILED (failures=1)\n",
    "```"
   ]
  },
  {
   "cell_type": "markdown",
   "metadata": {},
   "source": [
    "> - `unittest` 내장 모듈에 있는 `TestCase` 클래스의 하위 클래스를 정의하고 테스트하려는 동작마다 메서드를 정의함으로써 테스트를 정의할 수 있다. `TestCase` 하위 클래스 안에서 테스트 메서드의 이름은 test로 시작해야 한다.\n",
    "> - 테스트 안에서는 파이썬 내장 `assert` 문을 사용하지 말고, `assertEqual`과 같이 `TestCase` 클래스에 정의된 여러 가지 헬퍼 메서드를 사용해 원하는 동작을 확인한다.\n",
    "> - 준비 코드를 줄이려면 `subTest` 헬퍼 메서드를 사용해 데이터 기반 테스트를 정의하라."
   ]
  }
 ],
 "metadata": {
  "kernelspec": {
   "display_name": "Python 3",
   "language": "python",
   "name": "python3"
  },
  "language_info": {
   "codemirror_mode": {
    "name": "ipython",
    "version": 3
   },
   "file_extension": ".py",
   "mimetype": "text/x-python",
   "name": "python",
   "nbconvert_exporter": "python",
   "pygments_lexer": "ipython3",
   "version": "3.8.7"
  }
 },
 "nbformat": 4,
 "nbformat_minor": 4
}
